Exception in thread Thread-1:
Traceback (most recent call last):
  File "C:\Users\kenneth.cruickshank\AppData\Local\Programs\Python\Python38\lib\site-packages\paramiko\channel.py", line 699, in recv
    out = self.in_buffer.read(nbytes, self.timeout)
  File "C:\Users\kenneth.cruickshank\AppData\Local\Programs\Python\Python38\lib\site-packages\paramiko\buffered_pipe.py", line 164, in read
    raise PipeTimeout()
paramiko.buffered_pipe.PipeTimeout

During handling of the above exception, another exception occurred:

Traceback (most recent call last):
  File "C:\Users\kenneth.cruickshank\AppData\Local\Programs\Python\Python38\lib\site-packages\netmiko\base_connection.py", line 550, in _read_channel_expect
    new_data = self.remote_conn.recv(MAX_BUFFER)
  File "C:\Users\kenneth.cruickshank\AppData\Local\Programs\Python\Python38\lib\site-packages\paramiko\channel.py", line 701, in recv
    raise socket.timeout()
socket.timeout

During handling of the above exception, another exception occurred:

Traceback (most recent call last):
  File "C:\Users\kenneth.cruickshank\AppData\Local\Programs\Python\Python38\lib\threading.py", line 932, in _bootstrap_inner
    self.run()
  File "C:\Users\kenneth.cruickshank\AppData\Local\Programs\Python\Python38\lib\threading.py", line 870, in run
    self._target(*self._args, **self._kwargs)
  File "c:/Scripts/Switch Updates/playing.py", line 148, in deviceconnector
    net_connect.save_config()
  File "C:\Users\kenneth.cruickshank\AppData\Local\Programs\Python\Python38\lib\site-packages\netmiko\cisco\cisco_ios.py", line 33, in save_config
    return super().save_config(
  File "C:\Users\kenneth.cruickshank\AppData\Local\Programs\Python\Python38\lib\site-packages\netmiko\cisco_base_connection.py", line 203, in save_config
    self.enable()
  File "C:\Users\kenneth.cruickshank\AppData\Local\Programs\Python\Python38\lib\site-packages\netmiko\cisco_base_connection.py", line 18, in enable
    return super().enable(cmd=cmd, pattern=pattern, re_flags=re_flags)
  File "C:\Users\kenneth.cruickshank\AppData\Local\Programs\Python\Python38\lib\site-packages\netmiko\base_connection.py", line 1563, in enable
    if not self.check_enable_mode():
  File "C:\Users\kenneth.cruickshank\AppData\Local\Programs\Python\Python38\lib\site-packages\netmiko\cisco_base_connection.py", line 14, in check_enable_mode
    return super().check_enable_mode(check_string=check_string)
  File "C:\Users\kenneth.cruickshank\AppData\Local\Programs\Python\Python38\lib\site-packages\netmiko\base_connection.py", line 1543, in check_enable_mode
    output = self.read_until_prompt()
  File "C:\Users\kenneth.cruickshank\AppData\Local\Programs\Python\Python38\lib\site-packages\netmiko\base_connection.py", line 623, in read_until_prompt
    return self._read_channel_expect(*args, **kwargs)
  File "C:\Users\kenneth.cruickshank\AppData\Local\Programs\Python\Python38\lib\site-packages\netmiko\base_connection.py", line 560, in _read_channel_expect
    raise NetmikoTimeoutException(
netmiko.ssh_exception.NetmikoTimeoutException: Timed-out reading channel, data not available.